<?xml version='1.0'?>
<sdf version='1.9'>
    <model name="2R_planar_robot">
        <static>false</static>
        
        
        <link name="l1">
            <pose>0 0 0 0 0 0</pose>
            <collision name="l1_collision">
                <geometry>
                    <cylinder>
                        <radius>0.07</radius>
                        <length>0.5</length>
                    </cylinder>
                </geometry>
            </collision>
            <visual name="l1_visual">
                <pose>0.25 0 0 0 1.6 0</pose>
                <geometry>
                    <cylinder>
                        <radius>0.05</radius>
                        <length>0.5</length>
                    </cylinder>
                </geometry>
            </visual>
            <visual name="l1_joint_case">
                <pose>0 0 0 0 0 0</pose>
                <geometry>
                    <cylinder>
                        <radius>0.08</radius>
                        <length>0.15</length>
                    </cylinder>
                </geometry>
                <material>
                    <diffuse>0.98 0.22 0.1 1</diffuse>
                </material>
            </visual>
        </link>
        
        
        <link name="l2">
            <pose>0.5 0 0 0 0 0</pose>
            <collision name="l2_collision">
                <geometry>
                    <cylinder>
                        <radius>0.07</radius>
                        <length>0.5</length>
                    </cylinder>
                </geometry>
            </collision>
            <visual name="l2_visual">
                <pose>0.25 0 0.0 -1.6 0 -1.6</pose>
                <geometry>
                    <cylinder>
                        <radius>0.03</radius>
                        <length>0.5</length>
                    </cylinder>
                </geometry>
            </visual>
            <visual name="l2_joint_case">
                <pose>0 0 0 0 0 0</pose>
                <geometry>
                    <cylinder>
                        <radius>0.05</radius>
                        <length>0.1</length>
                    </cylinder>
                </geometry>
                 <material>
                    <diffuse>0.98 0.22 0.1 1</diffuse>
                </material>
            </visual>
        </link>
        
        <joint name='q1' type='revolute'>
            <parent>world</parent>
            <child>l1</child>
            <pose>0 0 0  0 0 0  </pose>
            <axis>
                <xyz>0 0 1</xyz>
                <limit>
                    <lower>0.0</lower>
                    <upper>3.14</upper>
                </limit>
            </axis>
        </joint>
        
        
        <joint name='q2' type='revolute'>
            <parent>l1</parent>
            <child>l2</child>
            <pose relative_to='l2'>0 0 0 0 0 0</pose>
            <axis>
                <xyz>0 0 1</xyz>
                <limit>
                    <lower>0</lower>
                    <upper>3.14</upper>
                </limit>
            </axis>
        </joint>
        

    </model>
</sdf>

